<mujoco model="bhand_model">
  <compiler angle="radian" autolimits="true" />
  <option gravity="0 0 0" timestep="0.001" />
  <visual>
    <global offwidth="3840" offheight="2160" />
  </visual>
  <asset>
    <mesh name="base_link_cylinder_collision000" content_type="model/obj" file="meshes/collision/base_link_cylinder_collision000.obj" />
    <mesh name="prox_link_cylinder_collision000" content_type="model/obj" file="meshes/collision/prox_link_cylinder_collision000.obj" />
    <texture type="skybox" builtin="gradient" rgb1="1 1 1" rgb2="1 1 1" width="32" height="512" />
  </asset>
  <worldbody>
    <light pos="0 0 5" dir="0 0 -1" directional="true" />
    <body name="hand_root">
      <body name="base_link">
        <inertial pos="-1.53445e-05 -0.00277694 0.0352882" quat="0.438804 0.898562 0.00566895 -0.00225058" mass="0.377966" diaginertia="0.00042733 0.000400804 0.000337306" />
        <geom type="mesh" mesh="base_link_cylinder_collision000" group="1" rgba="0.9 0.35 0.1 0.65" />
        <geom size="0.013 0.054 0.013" pos="0 -0.011 0.054" type="box" group="1" rgba="0.9 0.35 0.1 0.65" />
        <geom size="0.038 0.023 0.007" pos="0 0 0.072" type="box" group="1" rgba="0.9 0.35 0.1 0.65" />
        <geom size="0.013 0.01 0.005" pos="0 0.032 0.068" quat="0.981048 -0.193767 0 0" type="box" group="1" rgba="0.9 0.35 0.1 0.65" />
        <geom size="0.013 0.01 0.005" pos="0 -0.035 0.07" quat="0.870293 -0.492535 0 0" type="box" group="1" rgba="0.9 0.35 0.1 0.65" />
        <body name="finger_1_prox_link" pos="0.025 0 0.0415" quat="0.707105 0 0 -0.707108">
          <inertial pos="-0.288649 0.00099838 0.171253" quat="0.54962 0.438092 0.426 0.569664" mass="0.561431" diaginertia="0.000339591 0.000307549 9.05655e-05" />
          <joint name="finger_1_prox_joint" pos="0 0 0" axis="0 0 1" range="-3.14 0" damping="0.1" armature="0.0002" frictionloss="0.0" />
          <geom type="mesh" mesh="prox_link_cylinder_collision000" group="1" rgba="0.9 0.35 0.1 0.65" />
          <geom size="0.035 0.012 0.013" pos="-0.029 0 0.012" type="box" group="1" rgba="0.9 0.35 0.1 0.65" />
          <geom size="0.01 0.013 0.005" pos="-0.036 0 0.03" quat="0.870539 0 0.4921 0" type="box" group="1" rgba="0.9 0.35 0.1 0.65" />
          <body name="finger_1_med_liink" pos="-0.05 0 0.0339" quat="0.707105 0.707108 0 0">
            <inertial pos="-0.0309182 0.0019693 0.00074337" quat="-0.0214282 0.707188 0.0177553 0.706477" mass="0.313211" diaginertia="0.000177657 0.000174065 2.13826e-05" />
            <joint name="finger_1_med_joint" pos="0 0 0" axis="0 0 1" range="-2.44 0" damping="0.1" armature="0.0002" frictionloss="0.0" />
            <geom size="0.018 0.012 0.009" pos="-0.04 0.003 0.001" type="box" group="1" rgba="0.9 0.35 0.1 0.65" />
            <geom size="0.016 0.011 0.005" pos="-0.006 0.001 0.001" type="box" group="1" rgba="0.9 0.35 0.1 0.65" />
            <geom size="0.01 0.011 0.005" pos="-0.068 0.003 0.001" type="box" group="1" rgba="0.9 0.35 0.1 0.65" />
            <geom size="0.004 0.011 0.009" pos="-0.019 0.001 0.001" type="box" group="1" rgba="0.9 0.35 0.1 0.65" />
            <body name="finger_1_dist_link" pos="-0.069936 0.003 0" quat="1 0 0 0">
              <inertial pos="-0.0183315 0.0175634 0.000497128" quat="0.251159 0.315294 0.632663 0.661246" mass="0.193423" diaginertia="6.47196e-05 5.98921e-05 1.29472e-05" />
              <joint name="finger_1_dist_joint" pos="0 0 0" axis="0 0 1" range="-0.785 0" damping="0.1" armature="0.0002" frictionloss="0.0" />
              <geom size="0.007 0.019 0.01" pos="-0.022 0.023 0" quat="0.900708 0 0 0.434425" type="box" group="1" rgba="0.9 0.35 0.1 0.65" />
              <geom size="0.009 0.011 0.01" pos="-0.002 0.002 0" quat="0.925554 0 0 0.378616" type="box" group="1" rgba="0.9 0.35 0.1 0.65" />
              <geom size="0.006 0.006 0.01" pos="-0.038 0.034 0" quat="0.691668 0 0 0.722215" type="box" group="1" rgba="0.9 0.35 0.1 0.65" />
            </body>
          </body>
        </body>
        <body name="finger_2_prox_link" pos="-0.025 0 0.0415" quat="0.707105 0 0 -0.707108">
          <inertial pos="-0.288649 0.00099838 0.171253" quat="0.54962 0.438092 0.426 0.569664" mass="0.561431" diaginertia="0.000339591 0.000307549 9.05655e-05" />
          <joint name="finger_2_prox_joint" pos="0 0 0" axis="0 0 1" range="0 3.14" damping="0.1" armature="0.0002" frictionloss="0.0" />
          <geom type="mesh" mesh="prox_link_cylinder_collision000" group="1" rgba="0.9 0.35 0.1 0.65" />
          <geom size="0.035 0.012 0.013" pos="-0.029 0 0.012" type="box" group="1" rgba="0.9 0.35 0.1 0.65" />
          <geom size="0.01 0.013 0.005" pos="-0.036 0 0.03" quat="0.870539 0 0.4921 0" type="box" group="1" rgba="0.9 0.35 0.1 0.65" />
          <body name="finger_2_med_link" pos="-0.05 0 0.0339" quat="0.707105 0.707108 0 0">
            <inertial pos="-0.0309061 0.00214998 0.00074337" quat="-0.0236473 0.707137 0.0196672 0.706407" mass="0.313211" diaginertia="0.000177657 0.000174065 2.13826e-05" />
            <joint name="finger_2_med_joint" pos="0 0 0" axis="0 0 1" range="-2.44 0" damping="0.1" armature="0.0002" frictionloss="0.0" />
            <geom size="0.018 0.012 0.009" pos="-0.04 0.003 0.001" type="box" group="1" rgba="0.9 0.35 0.1 0.65" />
            <geom size="0.016 0.011 0.005" pos="-0.006 0.001 0.001" type="box" group="1" rgba="0.9 0.35 0.1 0.65" />
            <geom size="0.01 0.011 0.005" pos="-0.068 0.003 0.001" type="box" group="1" rgba="0.9 0.35 0.1 0.65" />
            <geom size="0.004 0.011 0.009" pos="-0.019 0.001 0.001" type="box" group="1" rgba="0.9 0.35 0.1 0.65" />
            <body name="finger_2_dist_link" pos="-0.069917 0.0034087 0">
              <inertial pos="-0.0181941 0.0177057 0.000497128" quat="0.248532 0.312878 0.633924 0.662178" mass="0.193423" diaginertia="6.47197e-05 5.9892e-05 1.29472e-05" />
              <joint name="finger_2_dist_joint" pos="0 0 0" axis="0 0 1" range="-0.785 0" damping="0.1" armature="0.0002" frictionloss="0.0" />
              <geom size="0.007 0.019 0.01" pos="-0.022 0.023 0" quat="0.900708 0 0 0.434425" type="box" group="1" rgba="0.9 0.35 0.1 0.65" />
              <geom size="0.009 0.011 0.01" pos="-0.002 0.002 0" quat="0.925554 0 0 0.378616" type="box" group="1" rgba="0.9 0.35 0.1 0.65" />
              <geom size="0.006 0.006 0.01" pos="-0.038 0.034 0" quat="0.691668 0 0 0.722215" type="box" group="1" rgba="0.9 0.35 0.1 0.65" />
            </body>
          </body>
        </body>
        <body name="finger_3_med_link" pos="0 -0.05 0.0754" quat="0.499998 0.5 0.500002 0.5">
          <inertial pos="-0.0309182 0.0019693 0.00074337" quat="-0.0214282 0.707188 0.0177553 0.706477" mass="0.313211" diaginertia="0.000177657 0.000174065 2.13826e-05" />
          <joint name="finger_3_med_joint" pos="0 0 0" axis="0 0 1" range="-2.44 0" damping="0.1" armature="0.0002" frictionloss="0.0" />
          <geom size="0.018 0.012 0.009" pos="-0.04 0.003 0.001" type="box" group="1" rgba="0.9 0.35 0.1 0.65" />
          <geom size="0.016 0.011 0.005" pos="-0.006 0.001 0.001" type="box" group="1" rgba="0.9 0.35 0.1 0.65" />
          <geom size="0.01 0.011 0.005" pos="-0.068 0.003 0.001" type="box" group="1" rgba="0.9 0.35 0.1 0.65" />
          <geom size="0.004 0.011 0.009" pos="-0.019 0.001 0.001" type="box" group="1" rgba="0.9 0.35 0.1 0.65" />
          <body name="finger_3_dist_link" pos="-0.069936 0.003 0">
            <inertial pos="-0.0183315 0.0175634 0.000497128" quat="0.251159 0.315294 0.632663 0.661246" mass="0.193423" diaginertia="6.47196e-05 5.98921e-05 1.29472e-05" />
            <joint name="finger_3_dist_joint" pos="0 0 0" axis="0 0 1" range="-0.785 0" damping="0.1" armature="0.0002" frictionloss="0.0" />
            <geom size="0.007 0.019 0.01" pos="-0.022 0.023 0" quat="0.900708 0 0 0.434425" type="box" group="1" rgba="0.9 0.35 0.1 0.65" />
            <geom size="0.009 0.011 0.01" pos="-0.002 0.002 0" quat="0.925554 0 0 0.378616" type="box" group="1" rgba="0.9 0.35 0.1 0.65" />
            <geom size="0.006 0.006 0.01" pos="-0.038 0.034 0" quat="0.691668 0 0 0.722215" type="box" group="1" rgba="0.9 0.35 0.1 0.65" />
          </body>
        </body>
      </body>
    </body>
  </worldbody>
  <contact>
    <exclude name="ex_base_link_finger_1_prox_link" body1="base_link" body2="finger_1_prox_link" />
    <exclude name="ex_finger_1_prox_link_finger_1_med_liink" body1="finger_1_prox_link" body2="finger_1_med_liink" />
    <exclude name="ex_finger_1_med_liink_finger_1_dist_link" body1="finger_1_med_liink" body2="finger_1_dist_link" />
    <exclude name="ex_base_link_finger_2_prox_link" body1="base_link" body2="finger_2_prox_link" />
    <exclude name="ex_finger_2_prox_link_finger_2_med_link" body1="finger_2_prox_link" body2="finger_2_med_link" />
    <exclude name="ex_finger_2_med_link_finger_2_dist_link" body1="finger_2_med_link" body2="finger_2_dist_link" />
    <exclude name="ex_base_link_finger_3_med_link" body1="base_link" body2="finger_3_med_link" />
    <exclude name="ex_finger_3_med_link_finger_3_dist_link" body1="finger_3_med_link" body2="finger_3_dist_link" />
  </contact>
  <equality />
  <actuator>
    <position name="finger_1_prox_joint_actuator" joint="finger_1_prox_joint" kp="1" forcerange="-1 1" ctrlrange="-3.14 0" />
    <position name="finger_1_med_joint_actuator" joint="finger_1_med_joint" kp="1" forcerange="-1 1" ctrlrange="-2.44 0" />
    <position name="finger_1_dist_joint_actuator" joint="finger_1_dist_joint" kp="1" forcerange="-1 1" ctrlrange="-0.785 0" />
    <position name="finger_2_prox_joint_actuator" joint="finger_2_prox_joint" kp="1" forcerange="-1 1" ctrlrange="0 3.14" />
    <position name="finger_2_med_joint_actuator" joint="finger_2_med_joint" kp="1" forcerange="-1 1" ctrlrange="-2.44 0" />
    <position name="finger_2_dist_joint_actuator" joint="finger_2_dist_joint" kp="1" forcerange="-1 1" ctrlrange="-0.785 0" />
    <position name="finger_3_med_joint_actuator" joint="finger_3_med_joint" kp="1" forcerange="-1 1" ctrlrange="-2.44 0" />
    <position name="finger_3_dist_joint_actuator" joint="finger_3_dist_joint" kp="1" forcerange="-1 1" ctrlrange="-0.785 0" />
  </actuator>
</mujoco>